<?xml version="1.0"?>
<robot name="wheel" xmlns:xacro="http://www.ros.org/wiki/xacro">

  <xacro:include filename="$(find pvcchair_description)/urdf/includes/parameters.xacro" />

  <xacro:macro name="wheel" params="suffix parent xyz">
    <link name="wheel_${suffix}_link">
      <inertial>
        <mass value="0.020000" />
        <origin xyz="0 0 0" />
        <inertia ixx="0.000030" ixy="0.000000" ixz="0.000000"
                                iyy="0.000030" iyz="0.000000"
                                               izz="0.000058" />
      </inertial>
      <visual>
        <origin xyz="0 0 0" rpy="${pi/2} 0 0" />
        <geometry>
          <cylinder radius="${wheel_radius}" length="0.0254" />
        </geometry>
        <material name="black">
          <color rgba="0 0 0 1" />
        </material>
      </visual>
      <collision>
        <origin xyz="0 0 0" rpy="${pi/2} 0 0" />
        <geometry>
          <cylinder radius="${wheel_radius}" length="0.0254" />
        </geometry>
      </collision>
    </link>
    <joint name="wheel_${suffix}" type="continuous">
      <axis xyz="0 1 0" />
      <origin xyz="${xyz}" rpy="0 0 0" />
      <parent link="${parent}" />
      <child link="wheel_${suffix}_link" />
    </joint>
  </xacro:macro>

</robot>
