<?xml version="1.0" ?>
<!-- =================================================================================== -->
<!-- |    This document was autogenerated by xacro from /home/paign10/pvc-powerchair/software/ros/src/pvcchair_description/urdf/pvcchair.urdf.xacro | -->
<!-- |    EDITING THIS FILE BY HAND IS NOT RECOMMENDED                                 | -->
<!-- =================================================================================== -->
<robot name="pvcchair" xmlns:xacro="http://www.ros.org/wiki/xacro">
  <link name="base_footprint"/>
  <!-- <xacro:property name="gearbox_plate_mesh">
    <mesh filename="package://pvcchair_description/meshes/wheel.dae" />
  </xacro:property> -->
  <!-- <xacro:property name="gearbox_plate_mesh">
    <mesh filename="package://pvcchair_description/meshes/caster.dae" />
  </xacro:property> -->
  <link name="base_link">
    <inertial>
      <mass value="0.045937"/>
      <origin xyz="0 0 0"/>
      <inertia ixx="0.000160" ixy="0.000000" ixz="0.000000" iyy="0.000004" iyz="0.000000" izz="0.000160"/>
    </inertial>
    <visual>
      <origin rpy="0 1.57079632679 1.57079632679" xyz="0 0 0"/>
      <geometry>
        <mesh filename="package://pvcchair_description/meshes/piping/p2_front_n_back_base.dae"/>
      </geometry>
    </visual>
    <collision>
      <origin rpy="0 1.57079632679 1.57079632679" xyz="0 0 0"/>
      <geometry>
        <mesh filename="package://pvcchair_description/meshes/piping/p2_front_n_back_base.dae"/>
      </geometry>
    </collision>
    <visual>
      <origin rpy="0 1.57079632679 0" xyz="0 -0.13335 0"/>
      <geometry>
        <mesh filename="package://pvcchair_description/meshes/connectors/cf_3_way_slip.dae"/>
      </geometry>
    </visual>
    <collision>
      <origin rpy="0 1.57079632679 0" xyz="0 -0.13335 0"/>
      <geometry>
        <mesh filename="package://pvcchair_description/meshes/connectors/cf_3_way_slip.dae"/>
      </geometry>
    </collision>
    <visual>
      <origin rpy="0 1.57079632679 3.14159265359" xyz="0 0.13335 0"/>
      <geometry>
        <mesh filename="package://pvcchair_description/meshes/connectors/cf_3_way_slip.dae"/>
      </geometry>
    </visual>
    <collision>
      <origin rpy="0 1.57079632679 3.14159265359" xyz="0 0.13335 0"/>
      <geometry>
        <mesh filename="package://pvcchair_description/meshes/connectors/cf_3_way_slip.dae"/>
      </geometry>
    </collision>
    <visual>
      <origin rpy="0 1.57079632679 0" xyz="0 -0.13335 0"/>
      <geometry>
        <mesh filename="package://pvcchair_description/meshes/piping/p1_left_n_right_base.dae"/>
      </geometry>
    </visual>
    <collision>
      <origin rpy="0 1.57079632679 0" xyz="0 -0.13335 0"/>
      <geometry>
        <mesh filename="package://pvcchair_description/meshes/piping/p1_left_n_right_base.dae"/>
      </geometry>
    </collision>
    <visual>
      <origin rpy="0 1.57079632679 0" xyz="0 0.13335 0"/>
      <geometry>
        <mesh filename="package://pvcchair_description/meshes/piping/p1_left_n_right_base.dae"/>
      </geometry>
    </visual>
    <collision>
      <origin rpy="0 1.57079632679 0" xyz="0 0.13335 0"/>
      <geometry>
        <mesh filename="package://pvcchair_description/meshes/piping/p1_left_n_right_base.dae"/>
      </geometry>
    </collision>
    <visual>
      <origin rpy="0 0 -1.57079632679" xyz="0.1143 -0.13335 0"/>
      <geometry>
        <mesh filename="package://pvcchair_description/meshes/connectors/cb_5_way_t_connect.dae"/>
      </geometry>
    </visual>
    <collision>
      <origin rpy="0 0 -1.57079632679" xyz="0.1143 -0.13335 0"/>
      <geometry>
        <mesh filename="package://pvcchair_description/meshes/connectors/cb_5_way_t_connect.dae"/>
      </geometry>
    </collision>
    <visual>
      <origin rpy="0 0 1.57079632679" xyz="0.1143 0.13335 0"/>
      <geometry>
        <mesh filename="package://pvcchair_description/meshes/connectors/cb_5_way_t_connect.dae"/>
      </geometry>
    </visual>
    <collision>
      <origin rpy="0 0 1.57079632679" xyz="0.1143 0.13335 0"/>
      <geometry>
        <mesh filename="package://pvcchair_description/meshes/connectors/cb_5_way_t_connect.dae"/>
      </geometry>
    </collision>
    <visual>
      <origin rpy="0 1.57079632679 1.57079632679" xyz="0.1143 0 0"/>
      <geometry>
        <mesh filename="package://pvcchair_description/meshes/piping/p2_front_n_back_base.dae"/>
      </geometry>
    </visual>
    <collision>
      <origin rpy="0 1.57079632679 1.57079632679" xyz="0.1143 0 0"/>
      <geometry>
        <mesh filename="package://pvcchair_description/meshes/piping/p2_front_n_back_base.dae"/>
      </geometry>
    </collision>
    <visual>
      <origin rpy="0 0 0" xyz="0.1143 -0.13335 0.0635"/>
      <geometry>
        <mesh filename="package://pvcchair_description/meshes/piping/p3_left_n_right_back_upright.dae"/>
      </geometry>
    </visual>
    <collision>
      <origin rpy="0 0 0" xyz="0.1143 -0.13335 0.0635"/>
      <geometry>
        <mesh filename="package://pvcchair_description/meshes/piping/p3_left_n_right_back_upright.dae"/>
      </geometry>
    </collision>
    <visual>
      <origin rpy="0 0 0" xyz="0.1143 0.13335 0.0635"/>
      <geometry>
        <mesh filename="package://pvcchair_description/meshes/piping/p3_left_n_right_back_upright.dae"/>
      </geometry>
    </visual>
    <collision>
      <origin rpy="0 0 0" xyz="0.1143 0.13335 0.0635"/>
      <geometry>
        <mesh filename="package://pvcchair_description/meshes/piping/p3_left_n_right_back_upright.dae"/>
      </geometry>
    </collision>
    <visual>
      <origin rpy="0 0 0" xyz="0.1143 -0.13335 -0.05715"/>
      <geometry>
        <mesh filename="package://pvcchair_description/meshes/piping/p4_footrest_base.dae"/>
      </geometry>
    </visual>
    <collision>
      <origin rpy="0 0 0" xyz="0.1143 -0.13335 -0.05715"/>
      <geometry>
        <mesh filename="package://pvcchair_description/meshes/piping/p4_footrest_base.dae"/>
      </geometry>
    </collision>
    <visual>
      <origin rpy="0 0 0" xyz="0.1143 0.13335 -0.05715"/>
      <geometry>
        <mesh filename="package://pvcchair_description/meshes/piping/p4_footrest_base.dae"/>
      </geometry>
    </visual>
    <collision>
      <origin rpy="0 0 0" xyz="0.1143 0.13335 -0.05715"/>
      <geometry>
        <mesh filename="package://pvcchair_description/meshes/piping/p4_footrest_base.dae"/>
      </geometry>
    </collision>
    <visual>
      <origin rpy="0 1.57079632679 0" xyz="0.17145 -0.13335 0"/>
      <geometry>
        <mesh filename="package://pvcchair_description/meshes/piping/p4_footrest_base.dae"/>
      </geometry>
    </visual>
    <collision>
      <origin rpy="0 1.57079632679 0" xyz="0.17145 -0.13335 0"/>
      <geometry>
        <mesh filename="package://pvcchair_description/meshes/piping/p4_footrest_base.dae"/>
      </geometry>
    </collision>
    <visual>
      <origin rpy="0 1.57079632679 0" xyz="0.17145 0.13335 0"/>
      <geometry>
        <mesh filename="package://pvcchair_description/meshes/piping/p4_footrest_base.dae"/>
      </geometry>
    </visual>
    <collision>
      <origin rpy="0 1.57079632679 0" xyz="0.17145 0.13335 0"/>
      <geometry>
        <mesh filename="package://pvcchair_description/meshes/piping/p4_footrest_base.dae"/>
      </geometry>
    </collision>
    <visual>
      <origin rpy="0 -1.57079632679 -1.57079632679" xyz="0.2286 -0.13335 0"/>
      <geometry>
        <mesh filename="package://pvcchair_description/meshes/connectors/cd_2_way_elbow.dae"/>
      </geometry>
    </visual>
    <collision>
      <origin rpy="0 -1.57079632679 -1.57079632679" xyz="0.2286 -0.13335 0"/>
      <geometry>
        <mesh filename="package://pvcchair_description/meshes/connectors/cd_2_way_elbow.dae"/>
      </geometry>
    </collision>
    <visual>
      <origin rpy="0 1.57079632679 -1.57079632679" xyz="0.2286 0.13335 0"/>
      <geometry>
        <mesh filename="package://pvcchair_description/meshes/connectors/cd_2_way_elbow.dae"/>
      </geometry>
    </visual>
    <collision>
      <origin rpy="0 1.57079632679 -1.57079632679" xyz="0.2286 0.13335 0"/>
      <geometry>
        <mesh filename="package://pvcchair_description/meshes/connectors/cd_2_way_elbow.dae"/>
      </geometry>
    </collision>
    <visual>
      <origin rpy="0 1.57079632679 1.57079632679" xyz="0.2286 0 0"/>
      <geometry>
        <mesh filename="package://pvcchair_description/meshes/piping/p2_front_n_back_base.dae"/>
      </geometry>
    </visual>
    <collision>
      <origin rpy="0 1.57079632679 1.57079632679" xyz="0.2286 0 0"/>
      <geometry>
        <mesh filename="package://pvcchair_description/meshes/piping/p2_front_n_back_base.dae"/>
      </geometry>
    </collision>
    <visual>
      <origin rpy="0 0 1.57079632679" xyz="-0.1143 -0.13335 0"/>
      <geometry>
        <mesh filename="package://pvcchair_description/meshes/connectors/cc_3_way_y_connect.dae"/>
      </geometry>
    </visual>
    <collision>
      <origin rpy="0 0 1.57079632679" xyz="-0.1143 -0.13335 0"/>
      <geometry>
        <mesh filename="package://pvcchair_description/meshes/connectors/cc_3_way_y_connect.dae"/>
      </geometry>
    </collision>
    <visual>
      <origin rpy="0 0 0" xyz="-0.1143 0.13335 0"/>
      <geometry>
        <mesh filename="package://pvcchair_description/meshes/connectors/cc_3_way_y_connect.dae"/>
      </geometry>
    </visual>
    <collision>
      <origin rpy="0 0 0" xyz="-0.1143 0.13335 0"/>
      <geometry>
        <mesh filename="package://pvcchair_description/meshes/connectors/cc_3_way_y_connect.dae"/>
      </geometry>
    </collision>
    <visual>
      <origin rpy="0 1.57079632679 1.57079632679" xyz="-0.1143 0 0"/>
      <geometry>
        <mesh filename="package://pvcchair_description/meshes/piping/p2_front_n_back_base.dae"/>
      </geometry>
    </visual>
    <collision>
      <origin rpy="0 1.57079632679 1.57079632679" xyz="-0.1143 0 0"/>
      <geometry>
        <mesh filename="package://pvcchair_description/meshes/piping/p2_front_n_back_base.dae"/>
      </geometry>
    </collision>
    <visual>
      <origin rpy="0 0 0" xyz="-0.1143 -0.13335 0.03175"/>
      <geometry>
        <mesh filename="package://pvcchair_description/meshes/piping/p9_connects_all.dae"/>
      </geometry>
    </visual>
    <collision>
      <origin rpy="0 0 0" xyz="-0.1143 -0.13335 0.03175"/>
      <geometry>
        <mesh filename="package://pvcchair_description/meshes/piping/p9_connects_all.dae"/>
      </geometry>
    </collision>
    <visual>
      <origin rpy="0 0 0" xyz="-0.1143 0.13335 0.03175"/>
      <geometry>
        <mesh filename="package://pvcchair_description/meshes/piping/p9_connects_all.dae"/>
      </geometry>
    </visual>
    <collision>
      <origin rpy="0 0 0" xyz="-0.1143 0.13335 0.03175"/>
      <geometry>
        <mesh filename="package://pvcchair_description/meshes/piping/p9_connects_all.dae"/>
      </geometry>
    </collision>
    <visual>
      <origin rpy="0 0 1.57079632679" xyz="-0.1143 -0.13335 0.0635"/>
      <geometry>
        <mesh filename="package://pvcchair_description/meshes/connectors/ce_3_way_t_connect.dae"/>
      </geometry>
    </visual>
    <collision>
      <origin rpy="0 0 1.57079632679" xyz="-0.1143 -0.13335 0.0635"/>
      <geometry>
        <mesh filename="package://pvcchair_description/meshes/connectors/ce_3_way_t_connect.dae"/>
      </geometry>
    </collision>
    <visual>
      <origin rpy="0 0 1.57079632679" xyz="-0.1143 0.13335 0.0635"/>
      <geometry>
        <mesh filename="package://pvcchair_description/meshes/connectors/ce_3_way_t_connect.dae"/>
      </geometry>
    </visual>
    <collision>
      <origin rpy="0 0 1.57079632679" xyz="-0.1143 0.13335 0.0635"/>
      <geometry>
        <mesh filename="package://pvcchair_description/meshes/connectors/ce_3_way_t_connect.dae"/>
      </geometry>
    </collision>
    <visual>
      <origin rpy="0 0 0" xyz="-0.1143 -0.13335 0.09525"/>
      <geometry>
        <mesh filename="package://pvcchair_description/meshes/piping/p9_connects_all.dae"/>
      </geometry>
    </visual>
    <collision>
      <origin rpy="0 0 0" xyz="-0.1143 -0.13335 0.09525"/>
      <geometry>
        <mesh filename="package://pvcchair_description/meshes/piping/p9_connects_all.dae"/>
      </geometry>
    </collision>
    <visual>
      <origin rpy="0 0 0" xyz="-0.1143 0.13335 0.09525"/>
      <geometry>
        <mesh filename="package://pvcchair_description/meshes/piping/p9_connects_all.dae"/>
      </geometry>
    </visual>
    <collision>
      <origin rpy="0 0 0" xyz="-0.1143 0.13335 0.09525"/>
      <geometry>
        <mesh filename="package://pvcchair_description/meshes/piping/p9_connects_all.dae"/>
      </geometry>
    </collision>
    <visual>
      <origin rpy="0 1.57079632679 0" xyz="-0.1778 -0.13335 0.0635"/>
      <geometry>
        <mesh filename="package://pvcchair_description/meshes/piping/p3_left_n_right_back_upright.dae"/>
      </geometry>
    </visual>
    <collision>
      <origin rpy="0 1.57079632679 0" xyz="-0.1778 -0.13335 0.0635"/>
      <geometry>
        <mesh filename="package://pvcchair_description/meshes/piping/p3_left_n_right_back_upright.dae"/>
      </geometry>
    </collision>
    <visual>
      <origin rpy="0 1.57079632679 0" xyz="-0.1778 0.13335 0.0635"/>
      <geometry>
        <mesh filename="package://pvcchair_description/meshes/piping/p3_left_n_right_back_upright.dae"/>
      </geometry>
    </visual>
    <collision>
      <origin rpy="0 1.57079632679 0" xyz="-0.1778 0.13335 0.0635"/>
      <geometry>
        <mesh filename="package://pvcchair_description/meshes/piping/p3_left_n_right_back_upright.dae"/>
      </geometry>
    </collision>
    <visual>
      <origin rpy="0 0 -1.57079632679" xyz="-0.2413 -0.13335 0.0635"/>
      <geometry>
        <mesh filename="package://pvcchair_description/meshes/connectors/ca_4_way_t_connect.dae"/>
      </geometry>
    </visual>
    <collision>
      <origin rpy="0 0 -1.57079632679" xyz="-0.2413 -0.13335 0.0635"/>
      <geometry>
        <mesh filename="package://pvcchair_description/meshes/connectors/ca_4_way_t_connect.dae"/>
      </geometry>
    </collision>
    <visual>
      <origin rpy="0 0 3.14159265359" xyz="-0.2413 0.13335 0.0635"/>
      <geometry>
        <mesh filename="package://pvcchair_description/meshes/connectors/ca_4_way_t_connect.dae"/>
      </geometry>
    </visual>
    <collision>
      <origin rpy="0 0 3.14159265359" xyz="-0.2413 0.13335 0.0635"/>
      <geometry>
        <mesh filename="package://pvcchair_description/meshes/connectors/ca_4_way_t_connect.dae"/>
      </geometry>
    </collision>
    <visual>
      <origin rpy="0 1.57079632679 1.57079632679" xyz="-0.2413 0 0.0635"/>
      <geometry>
        <mesh filename="package://pvcchair_description/meshes/piping/p2_front_n_back_base.dae"/>
      </geometry>
    </visual>
    <collision>
      <origin rpy="0 1.57079632679 1.57079632679" xyz="-0.2413 0 0.0635"/>
      <geometry>
        <mesh filename="package://pvcchair_description/meshes/piping/p2_front_n_back_base.dae"/>
      </geometry>
    </collision>
    <visual>
      <origin rpy="0 0 0" xyz="-0.2413 -0.13335 0.09525"/>
      <geometry>
        <mesh filename="package://pvcchair_description/meshes/piping/p9_connects_all.dae"/>
      </geometry>
    </visual>
    <collision>
      <origin rpy="0 0 0" xyz="-0.2413 -0.13335 0.09525"/>
      <geometry>
        <mesh filename="package://pvcchair_description/meshes/piping/p9_connects_all.dae"/>
      </geometry>
    </collision>
    <visual>
      <origin rpy="0 0 0" xyz="-0.2413 0.13335 0.09525"/>
      <geometry>
        <mesh filename="package://pvcchair_description/meshes/piping/p9_connects_all.dae"/>
      </geometry>
    </visual>
    <collision>
      <origin rpy="0 0 0" xyz="-0.2413 0.13335 0.09525"/>
      <geometry>
        <mesh filename="package://pvcchair_description/meshes/piping/p9_connects_all.dae"/>
      </geometry>
    </collision>
  </link>
  <link name="seat_link">
    <inertial>
      <mass value="0.045937"/>
      <origin xyz="0 0 0"/>
      <inertia ixx="0.000160" ixy="0.000000" ixz="0.000000" iyy="0.000004" iyz="0.000000" izz="0.000160"/>
    </inertial>
    <visual>
      <origin rpy="0 1.57079632679 1.57079632679" xyz="0 0 0"/>
      <geometry>
        <mesh filename="package://pvcchair_description/meshes/piping/p2_front_n_back_base.dae"/>
      </geometry>
    </visual>
    <collision>
      <origin rpy="0 1.57079632679 1.57079632679" xyz="0 0 0"/>
      <geometry>
        <mesh filename="package://pvcchair_description/meshes/piping/p2_front_n_back_base.dae"/>
      </geometry>
    </collision>
    <visual>
      <origin rpy="0 1.57079632679 0" xyz="0 -0.13335 0"/>
      <geometry>
        <mesh filename="package://pvcchair_description/meshes/connectors/ca_4_way_t_connect.dae"/>
      </geometry>
    </visual>
    <collision>
      <origin rpy="0 1.57079632679 0" xyz="0 -0.13335 0"/>
      <geometry>
        <mesh filename="package://pvcchair_description/meshes/connectors/ca_4_way_t_connect.dae"/>
      </geometry>
    </collision>
    <visual>
      <origin rpy="0 1.57079632679 3.14159265359" xyz="0 0.13335 0"/>
      <geometry>
        <mesh filename="package://pvcchair_description/meshes/connectors/ca_4_way_t_connect.dae"/>
      </geometry>
    </visual>
    <collision>
      <origin rpy="0 1.57079632679 3.14159265359" xyz="0 0.13335 0"/>
      <geometry>
        <mesh filename="package://pvcchair_description/meshes/connectors/ca_4_way_t_connect.dae"/>
      </geometry>
    </collision>
    <visual>
      <origin rpy="0 0 0" xyz="0 -0.13335 0.03175"/>
      <geometry>
        <mesh filename="package://pvcchair_description/meshes/piping/p8_arm_rest_hgt_back_n_arms.dae"/>
      </geometry>
    </visual>
    <collision>
      <origin rpy="0 0 0" xyz="0 -0.13335 0.03175"/>
      <geometry>
        <mesh filename="package://pvcchair_description/meshes/piping/p8_arm_rest_hgt_back_n_arms.dae"/>
      </geometry>
    </collision>
    <visual>
      <origin rpy="0 0 0" xyz="0 0.13335 0.03175"/>
      <geometry>
        <mesh filename="package://pvcchair_description/meshes/piping/p8_arm_rest_hgt_back_n_arms.dae"/>
      </geometry>
    </visual>
    <collision>
      <origin rpy="0 0 0" xyz="0 0.13335 0.03175"/>
      <geometry>
        <mesh filename="package://pvcchair_description/meshes/piping/p8_arm_rest_hgt_back_n_arms.dae"/>
      </geometry>
    </collision>
    <visual>
      <origin rpy="0 1.57079632679 0" xyz="0.05715 -0.13335 0"/>
      <geometry>
        <mesh filename="package://pvcchair_description/meshes/piping/p4_footrest_base.dae"/>
      </geometry>
    </visual>
    <collision>
      <origin rpy="0 1.57079632679 0" xyz="0.05715 -0.13335 0"/>
      <geometry>
        <mesh filename="package://pvcchair_description/meshes/piping/p4_footrest_base.dae"/>
      </geometry>
    </collision>
    <visual>
      <origin rpy="0 1.57079632679 0" xyz="0.05715 0.13335 0"/>
      <geometry>
        <mesh filename="package://pvcchair_description/meshes/piping/p4_footrest_base.dae"/>
      </geometry>
    </visual>
    <collision>
      <origin rpy="0 1.57079632679 0" xyz="0.05715 0.13335 0"/>
      <geometry>
        <mesh filename="package://pvcchair_description/meshes/piping/p4_footrest_base.dae"/>
      </geometry>
    </collision>
    <visual>
      <origin rpy="1.57079632679 0 3.14159265359" xyz="0.1143 -0.13335 0"/>
      <geometry>
        <mesh filename="package://pvcchair_description/meshes/connectors/cc_3_way_y_connect.dae"/>
      </geometry>
    </visual>
    <collision>
      <origin rpy="1.57079632679 0 3.14159265359" xyz="0.1143 -0.13335 0"/>
      <geometry>
        <mesh filename="package://pvcchair_description/meshes/connectors/cc_3_way_y_connect.dae"/>
      </geometry>
    </collision>
    <visual>
      <origin rpy="3.14159265359 0 3.14159265359" xyz="0.1143 0.13335 0"/>
      <geometry>
        <mesh filename="package://pvcchair_description/meshes/connectors/cc_3_way_y_connect.dae"/>
      </geometry>
    </visual>
    <collision>
      <origin rpy="3.14159265359 0 3.14159265359" xyz="0.1143 0.13335 0"/>
      <geometry>
        <mesh filename="package://pvcchair_description/meshes/connectors/cc_3_way_y_connect.dae"/>
      </geometry>
    </collision>
    <visual>
      <origin rpy="0 1.57079632679 1.57079632679" xyz="0.1143 0 0"/>
      <geometry>
        <mesh filename="package://pvcchair_description/meshes/piping/p2_front_n_back_base.dae"/>
      </geometry>
    </visual>
    <collision>
      <origin rpy="0 1.57079632679 1.57079632679" xyz="0.1143 0 0"/>
      <geometry>
        <mesh filename="package://pvcchair_description/meshes/piping/p2_front_n_back_base.dae"/>
      </geometry>
    </collision>
    <visual>
      <origin rpy="0 1.57079632679 0" xyz="-0.05715 -0.13335 0"/>
      <geometry>
        <mesh filename="package://pvcchair_description/meshes/piping/p4_footrest_base.dae"/>
      </geometry>
    </visual>
    <collision>
      <origin rpy="0 1.57079632679 0" xyz="-0.05715 -0.13335 0"/>
      <geometry>
        <mesh filename="package://pvcchair_description/meshes/piping/p4_footrest_base.dae"/>
      </geometry>
    </collision>
    <visual>
      <origin rpy="0 1.57079632679 0" xyz="-0.05715 0.13335 0"/>
      <geometry>
        <mesh filename="package://pvcchair_description/meshes/piping/p4_footrest_base.dae"/>
      </geometry>
    </visual>
    <collision>
      <origin rpy="0 1.57079632679 0" xyz="-0.05715 0.13335 0"/>
      <geometry>
        <mesh filename="package://pvcchair_description/meshes/piping/p4_footrest_base.dae"/>
      </geometry>
    </collision>
    <visual>
      <origin rpy="0 0 -1.57079632679" xyz="-0.1143 -0.13335 0"/>
      <geometry>
        <mesh filename="package://pvcchair_description/meshes/connectors/cb_5_way_t_connect.dae"/>
      </geometry>
    </visual>
    <collision>
      <origin rpy="0 0 -1.57079632679" xyz="-0.1143 -0.13335 0"/>
      <geometry>
        <mesh filename="package://pvcchair_description/meshes/connectors/cb_5_way_t_connect.dae"/>
      </geometry>
    </collision>
    <visual>
      <origin rpy="0 0 1.57079632679" xyz="-0.1143 0.13335 0"/>
      <geometry>
        <mesh filename="package://pvcchair_description/meshes/connectors/cb_5_way_t_connect.dae"/>
      </geometry>
    </visual>
    <collision>
      <origin rpy="0 0 1.57079632679" xyz="-0.1143 0.13335 0"/>
      <geometry>
        <mesh filename="package://pvcchair_description/meshes/connectors/cb_5_way_t_connect.dae"/>
      </geometry>
    </collision>
    <visual>
      <origin rpy="0 1.57079632679 1.57079632679" xyz="-0.1143 0 0"/>
      <geometry>
        <mesh filename="package://pvcchair_description/meshes/piping/p2_front_n_back_base.dae"/>
      </geometry>
    </visual>
    <collision>
      <origin rpy="0 1.57079632679 1.57079632679" xyz="-0.1143 0 0"/>
      <geometry>
        <mesh filename="package://pvcchair_description/meshes/piping/p2_front_n_back_base.dae"/>
      </geometry>
    </collision>
    <visual>
      <origin rpy="0 0 0" xyz="-0.1143 -0.13335 0.03175"/>
      <geometry>
        <mesh filename="package://pvcchair_description/meshes/piping/p8_arm_rest_hgt_back_n_arms.dae"/>
      </geometry>
    </visual>
    <collision>
      <origin rpy="0 0 0" xyz="-0.1143 -0.13335 0.03175"/>
      <geometry>
        <mesh filename="package://pvcchair_description/meshes/piping/p8_arm_rest_hgt_back_n_arms.dae"/>
      </geometry>
    </collision>
    <visual>
      <origin rpy="0 0 0" xyz="-0.1143 0.13335 0.03175"/>
      <geometry>
        <mesh filename="package://pvcchair_description/meshes/piping/p8_arm_rest_hgt_back_n_arms.dae"/>
      </geometry>
    </visual>
    <collision>
      <origin rpy="0 0 0" xyz="-0.1143 0.13335 0.03175"/>
      <geometry>
        <mesh filename="package://pvcchair_description/meshes/piping/p8_arm_rest_hgt_back_n_arms.dae"/>
      </geometry>
    </collision>
    <visual>
      <origin rpy="0 1.57079632679 0" xyz="-0.1778 -0.13335 0"/>
      <geometry>
        <mesh filename="package://pvcchair_description/meshes/piping/p3_left_n_right_back_upright.dae"/>
      </geometry>
    </visual>
    <collision>
      <origin rpy="0 1.57079632679 0" xyz="-0.1778 -0.13335 0"/>
      <geometry>
        <mesh filename="package://pvcchair_description/meshes/piping/p3_left_n_right_back_upright.dae"/>
      </geometry>
    </collision>
    <visual>
      <origin rpy="0 1.57079632679 0" xyz="-0.1778 0.13335 0"/>
      <geometry>
        <mesh filename="package://pvcchair_description/meshes/piping/p3_left_n_right_back_upright.dae"/>
      </geometry>
    </visual>
    <collision>
      <origin rpy="0 1.57079632679 0" xyz="-0.1778 0.13335 0"/>
      <geometry>
        <mesh filename="package://pvcchair_description/meshes/piping/p3_left_n_right_back_upright.dae"/>
      </geometry>
    </collision>
    <visual>
      <origin rpy="3.14159265359 0 0" xyz="-0.2413 -0.13335 0"/>
      <geometry>
        <mesh filename="package://pvcchair_description/meshes/connectors/cc_3_way_y_connect.dae"/>
      </geometry>
    </visual>
    <collision>
      <origin rpy="3.14159265359 0 0" xyz="-0.2413 -0.13335 0"/>
      <geometry>
        <mesh filename="package://pvcchair_description/meshes/connectors/cc_3_way_y_connect.dae"/>
      </geometry>
    </collision>
    <visual>
      <origin rpy="1.57079632679 0 0" xyz="-0.2413 0.13335 0"/>
      <geometry>
        <mesh filename="package://pvcchair_description/meshes/connectors/cc_3_way_y_connect.dae"/>
      </geometry>
    </visual>
    <collision>
      <origin rpy="1.57079632679 0 0" xyz="-0.2413 0.13335 0"/>
      <geometry>
        <mesh filename="package://pvcchair_description/meshes/connectors/cc_3_way_y_connect.dae"/>
      </geometry>
    </collision>
    <visual>
      <origin rpy="0 1.57079632679 1.57079632679" xyz="-0.2413 0 0"/>
      <geometry>
        <mesh filename="package://pvcchair_description/meshes/piping/p2_front_n_back_base.dae"/>
      </geometry>
    </visual>
    <collision>
      <origin rpy="0 1.57079632679 1.57079632679" xyz="-0.2413 0 0"/>
      <geometry>
        <mesh filename="package://pvcchair_description/meshes/piping/p2_front_n_back_base.dae"/>
      </geometry>
    </collision>
    <visual>
      <origin rpy="1.57079632679 -1.21300383014 0" xyz="-0.2413 0 0"/>
      <geometry>
        <mesh filename="package://pvcchair_description/meshes/connectors/cf_3_way_slip.dae"/>
      </geometry>
    </visual>
    <collision>
      <origin rpy="1.57079632679 -1.21300383014 0" xyz="-0.2413 0 0"/>
      <geometry>
        <mesh filename="package://pvcchair_description/meshes/connectors/cf_3_way_slip.dae"/>
      </geometry>
    </collision>
    <visual>
      <origin rpy="0 1.92858882345 0" xyz="-0.271039342009 0 0.011119084355"/>
      <geometry>
        <mesh filename="package://pvcchair_description/meshes/piping/p9_connects_all.dae"/>
      </geometry>
    </visual>
    <collision>
      <origin rpy="0 1.92858882345 0" xyz="-0.271039342009 0 0.011119084355"/>
      <geometry>
        <mesh filename="package://pvcchair_description/meshes/piping/p9_connects_all.dae"/>
      </geometry>
    </collision>
    <visual>
      <origin rpy="-0.357792496659 0 -1.57079632679" xyz="-0.300778684017 0 0.02223816871"/>
      <geometry>
        <mesh filename="package://pvcchair_description/meshes/connectors/cf_3_way_slip.dae"/>
      </geometry>
    </visual>
    <collision>
      <origin rpy="-0.357792496659 0 -1.57079632679" xyz="-0.300778684017 0 0.02223816871"/>
      <geometry>
        <mesh filename="package://pvcchair_description/meshes/connectors/cf_3_way_slip.dae"/>
      </geometry>
    </collision>
  </link>
  <link name="arms_link">
    <inertial>
      <mass value="0.045937"/>
      <origin xyz="0 0 0"/>
      <inertia ixx="0.000160" ixy="0.000000" ixz="0.000000" iyy="0.000004" iyz="0.000000" izz="0.000160"/>
    </inertial>
    <visual>
      <origin rpy="0 0 -1.57079632679" xyz="0 -0.13335 0"/>
      <geometry>
        <mesh filename="package://pvcchair_description/meshes/connectors/ca_4_way_t_connect.dae"/>
      </geometry>
    </visual>
    <collision>
      <origin rpy="0 0 -1.57079632679" xyz="0 -0.13335 0"/>
      <geometry>
        <mesh filename="package://pvcchair_description/meshes/connectors/ca_4_way_t_connect.dae"/>
      </geometry>
    </collision>
    <visual>
      <origin rpy="0 0 3.14159265359" xyz="0 0.13335 0"/>
      <geometry>
        <mesh filename="package://pvcchair_description/meshes/connectors/ca_4_way_t_connect.dae"/>
      </geometry>
    </visual>
    <collision>
      <origin rpy="0 0 3.14159265359" xyz="0 0.13335 0"/>
      <geometry>
        <mesh filename="package://pvcchair_description/meshes/connectors/ca_4_way_t_connect.dae"/>
      </geometry>
    </collision>
    <visual>
      <origin rpy="0 1.57079632679 0" xyz="0.05715 -0.13335 0"/>
      <geometry>
        <mesh filename="package://pvcchair_description/meshes/piping/p4_footrest_base.dae"/>
      </geometry>
    </visual>
    <collision>
      <origin rpy="0 1.57079632679 0" xyz="0.05715 -0.13335 0"/>
      <geometry>
        <mesh filename="package://pvcchair_description/meshes/piping/p4_footrest_base.dae"/>
      </geometry>
    </collision>
    <visual>
      <origin rpy="0 1.57079632679 0" xyz="0.05715 0.13335 0"/>
      <geometry>
        <mesh filename="package://pvcchair_description/meshes/piping/p4_footrest_base.dae"/>
      </geometry>
    </visual>
    <collision>
      <origin rpy="0 1.57079632679 0" xyz="0.05715 0.13335 0"/>
      <geometry>
        <mesh filename="package://pvcchair_description/meshes/piping/p4_footrest_base.dae"/>
      </geometry>
    </collision>
    <visual>
      <origin rpy="0 0 1.57079632679" xyz="0.1143 -0.13335 0"/>
      <geometry>
        <mesh filename="package://pvcchair_description/meshes/connectors/ce_3_way_t_connect.dae"/>
      </geometry>
    </visual>
    <collision>
      <origin rpy="0 0 1.57079632679" xyz="0.1143 -0.13335 0"/>
      <geometry>
        <mesh filename="package://pvcchair_description/meshes/connectors/ce_3_way_t_connect.dae"/>
      </geometry>
    </collision>
    <visual>
      <origin rpy="0 0 1.57079632679" xyz="0.1143 0.13335 0"/>
      <geometry>
        <mesh filename="package://pvcchair_description/meshes/connectors/ce_3_way_t_connect.dae"/>
      </geometry>
    </visual>
    <collision>
      <origin rpy="0 0 1.57079632679" xyz="0.1143 0.13335 0"/>
      <geometry>
        <mesh filename="package://pvcchair_description/meshes/connectors/ce_3_way_t_connect.dae"/>
      </geometry>
    </collision>
    <visual>
      <origin rpy="0 0 0" xyz="0 -0.13335 0.03175"/>
      <geometry>
        <mesh filename="package://pvcchair_description/meshes/piping/p8_arm_rest_hgt_back_n_arms.dae"/>
      </geometry>
    </visual>
    <collision>
      <origin rpy="0 0 0" xyz="0 -0.13335 0.03175"/>
      <geometry>
        <mesh filename="package://pvcchair_description/meshes/piping/p8_arm_rest_hgt_back_n_arms.dae"/>
      </geometry>
    </collision>
    <visual>
      <origin rpy="0 0 0" xyz="0 0.13335 0.03175"/>
      <geometry>
        <mesh filename="package://pvcchair_description/meshes/piping/p8_arm_rest_hgt_back_n_arms.dae"/>
      </geometry>
    </visual>
    <collision>
      <origin rpy="0 0 0" xyz="0 0.13335 0.03175"/>
      <geometry>
        <mesh filename="package://pvcchair_description/meshes/piping/p8_arm_rest_hgt_back_n_arms.dae"/>
      </geometry>
    </collision>
    <visual>
      <origin rpy="0 0 0" xyz="0.1143 -0.13335 0.03175"/>
      <geometry>
        <mesh filename="package://pvcchair_description/meshes/piping/p8_arm_rest_hgt_back_n_arms.dae"/>
      </geometry>
    </visual>
    <collision>
      <origin rpy="0 0 0" xyz="0.1143 -0.13335 0.03175"/>
      <geometry>
        <mesh filename="package://pvcchair_description/meshes/piping/p8_arm_rest_hgt_back_n_arms.dae"/>
      </geometry>
    </collision>
    <visual>
      <origin rpy="0 0 0" xyz="0.1143 0.13335 0.03175"/>
      <geometry>
        <mesh filename="package://pvcchair_description/meshes/piping/p8_arm_rest_hgt_back_n_arms.dae"/>
      </geometry>
    </visual>
    <collision>
      <origin rpy="0 0 0" xyz="0.1143 0.13335 0.03175"/>
      <geometry>
        <mesh filename="package://pvcchair_description/meshes/piping/p8_arm_rest_hgt_back_n_arms.dae"/>
      </geometry>
    </collision>
    <visual>
      <origin rpy="1.57079632679 0 1.57079632679" xyz="0 -0.13335 0.0635"/>
      <geometry>
        <mesh filename="package://pvcchair_description/meshes/connectors/cd_2_way_elbow.dae"/>
      </geometry>
    </visual>
    <collision>
      <origin rpy="1.57079632679 0 1.57079632679" xyz="0 -0.13335 0.0635"/>
      <geometry>
        <mesh filename="package://pvcchair_description/meshes/connectors/cd_2_way_elbow.dae"/>
      </geometry>
    </collision>
    <visual>
      <origin rpy="1.57079632679 0 1.57079632679" xyz="0 0.13335 0.0635"/>
      <geometry>
        <mesh filename="package://pvcchair_description/meshes/connectors/cd_2_way_elbow.dae"/>
      </geometry>
    </visual>
    <collision>
      <origin rpy="1.57079632679 0 1.57079632679" xyz="0 0.13335 0.0635"/>
      <geometry>
        <mesh filename="package://pvcchair_description/meshes/connectors/cd_2_way_elbow.dae"/>
      </geometry>
    </collision>
    <visual>
      <origin rpy="-1.57079632679 0 1.57079632679" xyz="0.1143 -0.13335 0.0635"/>
      <geometry>
        <mesh filename="package://pvcchair_description/meshes/connectors/cf_3_way_slip.dae"/>
      </geometry>
    </visual>
    <collision>
      <origin rpy="-1.57079632679 0 1.57079632679" xyz="0.1143 -0.13335 0.0635"/>
      <geometry>
        <mesh filename="package://pvcchair_description/meshes/connectors/cf_3_way_slip.dae"/>
      </geometry>
    </collision>
    <visual>
      <origin rpy="-1.57079632679 0 1.57079632679" xyz="0.1143 0.13335 0.0635"/>
      <geometry>
        <mesh filename="package://pvcchair_description/meshes/connectors/cf_3_way_slip.dae"/>
      </geometry>
    </visual>
    <collision>
      <origin rpy="-1.57079632679 0 1.57079632679" xyz="0.1143 0.13335 0.0635"/>
      <geometry>
        <mesh filename="package://pvcchair_description/meshes/connectors/cf_3_way_slip.dae"/>
      </geometry>
    </collision>
    <visual>
      <origin rpy="0 1.57079632679 0" xyz="0.085725 -0.13335 0.0635"/>
      <geometry>
        <mesh filename="package://pvcchair_description/meshes/piping/p6_back_rest_horz.dae"/>
      </geometry>
    </visual>
    <collision>
      <origin rpy="0 1.57079632679 0" xyz="0.085725 -0.13335 0.0635"/>
      <geometry>
        <mesh filename="package://pvcchair_description/meshes/piping/p6_back_rest_horz.dae"/>
      </geometry>
    </collision>
    <visual>
      <origin rpy="0 1.57079632679 0" xyz="0.085725 0.13335 0.0635"/>
      <geometry>
        <mesh filename="package://pvcchair_description/meshes/piping/p6_back_rest_horz.dae"/>
      </geometry>
    </visual>
    <collision>
      <origin rpy="0 1.57079632679 0" xyz="0.085725 0.13335 0.0635"/>
      <geometry>
        <mesh filename="package://pvcchair_description/meshes/piping/p6_back_rest_horz.dae"/>
      </geometry>
    </collision>
  </link>
  <link name="back_link">
    <inertial>
      <mass value="0.045937"/>
      <origin xyz="0 0 0"/>
      <inertia ixx="0.000160" ixy="0.000000" ixz="0.000000" iyy="0.000004" iyz="0.000000" izz="0.000160"/>
    </inertial>
    <visual>
      <origin rpy="0 1.57079632679 1.57079632679" xyz="0 0 0"/>
      <geometry>
        <mesh filename="package://pvcchair_description/meshes/piping/p2_front_n_back_base.dae"/>
      </geometry>
    </visual>
    <collision>
      <origin rpy="0 1.57079632679 1.57079632679" xyz="0 0 0"/>
      <geometry>
        <mesh filename="package://pvcchair_description/meshes/piping/p2_front_n_back_base.dae"/>
      </geometry>
    </collision>
    <visual>
      <origin rpy="1.57079632679 -0.349065850399 0" xyz="0 -0.085725 0"/>
      <geometry>
        <mesh filename="package://pvcchair_description/meshes/connectors/cf_3_way_slip.dae"/>
      </geometry>
    </visual>
    <collision>
      <origin rpy="1.57079632679 -0.349065850399 0" xyz="0 -0.085725 0"/>
      <geometry>
        <mesh filename="package://pvcchair_description/meshes/connectors/cf_3_way_slip.dae"/>
      </geometry>
    </collision>
    <visual>
      <origin rpy="1.57079632679 -0.349065850399 0" xyz="0 0.085725 0"/>
      <geometry>
        <mesh filename="package://pvcchair_description/meshes/connectors/cf_3_way_slip.dae"/>
      </geometry>
    </visual>
    <collision>
      <origin rpy="1.57079632679 -0.349065850399 0" xyz="0 0.085725 0"/>
      <geometry>
        <mesh filename="package://pvcchair_description/meshes/connectors/cf_3_way_slip.dae"/>
      </geometry>
    </collision>
    <visual>
      <origin rpy="0 -0.349065850399 0" xyz="-0.0108591395506 -0.085725 0.02983524071"/>
      <geometry>
        <mesh filename="package://pvcchair_description/meshes/piping/p9_connects_all.dae"/>
      </geometry>
    </visual>
    <collision>
      <origin rpy="0 -0.349065850399 0" xyz="-0.0108591395506 -0.085725 0.02983524071"/>
      <geometry>
        <mesh filename="package://pvcchair_description/meshes/piping/p9_connects_all.dae"/>
      </geometry>
    </collision>
    <visual>
      <origin rpy="0 -0.349065850399 0" xyz="-0.0108591395506 0.085725 0.02983524071"/>
      <geometry>
        <mesh filename="package://pvcchair_description/meshes/piping/p9_connects_all.dae"/>
      </geometry>
    </visual>
    <collision>
      <origin rpy="0 -0.349065850399 0" xyz="-0.0108591395506 0.085725 0.02983524071"/>
      <geometry>
        <mesh filename="package://pvcchair_description/meshes/piping/p9_connects_all.dae"/>
      </geometry>
    </collision>
    <visual>
      <origin rpy="0 -0.349065850399 0" xyz="-0.0217182791012 -0.085725 0.0596704814199"/>
      <geometry>
        <mesh filename="package://pvcchair_description/meshes/connectors/ce_3_way_t_connect.dae"/>
      </geometry>
    </visual>
    <collision>
      <origin rpy="0 -0.349065850399 0" xyz="-0.0217182791012 -0.085725 0.0596704814199"/>
      <geometry>
        <mesh filename="package://pvcchair_description/meshes/connectors/ce_3_way_t_connect.dae"/>
      </geometry>
    </collision>
    <visual>
      <origin rpy="0 0.349065850399 3.14159265359" xyz="-0.0217182791012 0.085725 0.0596704814199"/>
      <geometry>
        <mesh filename="package://pvcchair_description/meshes/connectors/ce_3_way_t_connect.dae"/>
      </geometry>
    </visual>
    <collision>
      <origin rpy="0 0.349065850399 3.14159265359" xyz="-0.0217182791012 0.085725 0.0596704814199"/>
      <geometry>
        <mesh filename="package://pvcchair_description/meshes/connectors/ce_3_way_t_connect.dae"/>
      </geometry>
    </collision>
    <visual>
      <origin rpy="0 1.57079632679 1.57079632679" xyz="-0.0217182791012 0 0.0596704814199"/>
      <geometry>
        <mesh filename="package://pvcchair_description/meshes/piping/p6_back_rest_horz.dae"/>
      </geometry>
    </visual>
    <collision>
      <origin rpy="0 1.57079632679 1.57079632679" xyz="-0.0217182791012 0 0.0596704814199"/>
      <geometry>
        <mesh filename="package://pvcchair_description/meshes/piping/p6_back_rest_horz.dae"/>
      </geometry>
    </collision>
    <visual>
      <origin rpy="0 -0.349065850399 0" xyz="-0.0521238698428 -0.085725 0.143209155408"/>
      <geometry>
        <mesh filename="package://pvcchair_description/meshes/piping/p5_back_rest_vert.dae"/>
      </geometry>
    </visual>
    <collision>
      <origin rpy="0 -0.349065850399 0" xyz="-0.0521238698428 -0.085725 0.143209155408"/>
      <geometry>
        <mesh filename="package://pvcchair_description/meshes/piping/p5_back_rest_vert.dae"/>
      </geometry>
    </collision>
    <visual>
      <origin rpy="0 -0.349065850399 0" xyz="-0.0521238698428 0.085725 0.143209155408"/>
      <geometry>
        <mesh filename="package://pvcchair_description/meshes/piping/p5_back_rest_vert.dae"/>
      </geometry>
    </visual>
    <collision>
      <origin rpy="0 -0.349065850399 0" xyz="-0.0521238698428 0.085725 0.143209155408"/>
      <geometry>
        <mesh filename="package://pvcchair_description/meshes/piping/p5_back_rest_vert.dae"/>
      </geometry>
    </collision>
    <visual>
      <origin rpy="3.14159265359 -0.349065850399 0" xyz="-0.0825294605845 -0.085725 0.226747829396"/>
      <geometry>
        <mesh filename="package://pvcchair_description/meshes/connectors/cd_2_way_elbow.dae"/>
      </geometry>
    </visual>
    <collision>
      <origin rpy="3.14159265359 -0.349065850399 0" xyz="-0.0825294605845 -0.085725 0.226747829396"/>
      <geometry>
        <mesh filename="package://pvcchair_description/meshes/connectors/cd_2_way_elbow.dae"/>
      </geometry>
    </collision>
    <visual>
      <origin rpy="1.57079632679 -0.349065850399 0" xyz="-0.0825294605845 0.085725 0.226747829396"/>
      <geometry>
        <mesh filename="package://pvcchair_description/meshes/connectors/cd_2_way_elbow.dae"/>
      </geometry>
    </visual>
    <collision>
      <origin rpy="1.57079632679 -0.349065850399 0" xyz="-0.0825294605845 0.085725 0.226747829396"/>
      <geometry>
        <mesh filename="package://pvcchair_description/meshes/connectors/cd_2_way_elbow.dae"/>
      </geometry>
    </collision>
    <visual>
      <origin rpy="0 1.57079632679 1.57079632679" xyz="-0.0825294605845 0 0.226747829396"/>
      <geometry>
        <mesh filename="package://pvcchair_description/meshes/piping/p6_back_rest_horz.dae"/>
      </geometry>
    </visual>
    <collision>
      <origin rpy="0 1.57079632679 1.57079632679" xyz="-0.0825294605845 0 0.226747829396"/>
      <geometry>
        <mesh filename="package://pvcchair_description/meshes/piping/p6_back_rest_horz.dae"/>
      </geometry>
    </collision>
    <visual>
      <origin rpy="1.57079632679 -2.77158285217 0" xyz="-0.0825294605845 0 0.226747829396"/>
      <geometry>
        <mesh filename="package://pvcchair_description/meshes/connectors/cf_3_way_slip.dae"/>
      </geometry>
    </visual>
    <collision>
      <origin rpy="1.57079632679 -2.77158285217 0" xyz="-0.0825294605845 0 0.226747829396"/>
      <geometry>
        <mesh filename="package://pvcchair_description/meshes/connectors/cf_3_way_slip.dae"/>
      </geometry>
    </collision>
    <visual>
      <origin rpy="0 0.370009801423 0" xyz="-0.138789203075 0 0.0817015540215"/>
      <geometry>
        <mesh filename="package://pvcchair_description/meshes/piping/p7_adjusting_pipe_horz.dae"/>
      </geometry>
    </visual>
    <collision>
      <origin rpy="0 0.370009801423 0" xyz="-0.138789203075 0 0.0817015540215"/>
      <geometry>
        <mesh filename="package://pvcchair_description/meshes/piping/p7_adjusting_pipe_horz.dae"/>
      </geometry>
    </collision>
  </link>
  <link name="gearbox_plate_right">
    <inertial>
      <mass value="0.080099"/>
      <origin xyz="-0.072510 0.001500 0.049147"/>
      <inertia ixx="0.000051" ixy="0.000000" ixz="0.000017" iyy="0.000150" iyz="0.000000" izz="0.000099"/>
    </inertial>
    <visual>
      <origin rpy="0 0 0" xyz="0 0 0"/>
      <geometry>
        <mesh filename="package://pvcchair_description/meshes/gearbox_plate.dae"/>
      </geometry>
    </visual>
    <collision>
      <origin rpy="0 0 0" xyz="0 0 0"/>
      <geometry>
        <mesh filename="package://pvcchair_description/meshes/gearbox_plate.dae"/>
      </geometry>
    </collision>
  </link>
  <link name="wheel_axle_right"/>
  <joint name="plate_wheel_right_joint" type="fixed">
    <origin rpy="0 0 0" xyz="-0.052 0 -0.054"/>
    <parent link="gearbox_plate_right"/>
    <child link="wheel_axle_right"/>
  </joint>
  <link name="gearbox_plate_left">
    <inertial>
      <mass value="0.080099"/>
      <origin xyz="-0.072510 0.001500 0.049147"/>
      <inertia ixx="0.000051" ixy="0.000000" ixz="0.000017" iyy="0.000150" iyz="0.000000" izz="0.000099"/>
    </inertial>
    <visual>
      <origin rpy="0 0 0" xyz="0 0 0"/>
      <geometry>
        <mesh filename="package://pvcchair_description/meshes/gearbox_plate.dae"/>
      </geometry>
    </visual>
    <collision>
      <origin rpy="0 0 0" xyz="0 0 0"/>
      <geometry>
        <mesh filename="package://pvcchair_description/meshes/gearbox_plate.dae"/>
      </geometry>
    </collision>
  </link>
  <link name="wheel_axle_left"/>
  <joint name="plate_wheel_left_joint" type="fixed">
    <origin rpy="0 0 0" xyz="-0.052 0 -0.054"/>
    <parent link="gearbox_plate_left"/>
    <child link="wheel_axle_left"/>
  </joint>
  <link name="wheel_right">
    <inertial>
      <mass value="0.020000"/>
      <origin xyz="0 0 0"/>
      <inertia ixx="0.000030" ixy="0.000000" ixz="0.000000" iyy="0.000030" iyz="0.000000" izz="0.000058"/>
    </inertial>
    <visual>
      <origin rpy="1.57079632679 0 0" xyz="0 0 0"/>
      <geometry>
        <cylinder length="0.0254" radius="0.0762"/>
      </geometry>
      <material name="Black">
        <color rgba="0 0 0 1"/>
      </material>
    </visual>
    <collision>
      <origin rpy="1.57079632679 0 0" xyz="0 0 0"/>
      <geometry>
        <cylinder length="0.0254" radius="0.0762"/>
      </geometry>
    </collision>
  </link>
  <link name="wheel_left">
    <inertial>
      <mass value="0.020000"/>
      <origin xyz="0 0 0"/>
      <inertia ixx="0.000030" ixy="0.000000" ixz="0.000000" iyy="0.000030" iyz="0.000000" izz="0.000058"/>
    </inertial>
    <visual>
      <origin rpy="1.57079632679 0 0" xyz="0 0 0"/>
      <geometry>
        <cylinder length="0.0254" radius="0.0762"/>
      </geometry>
      <material name="Black">
        <color rgba="0 0 0 1"/>
      </material>
    </visual>
    <collision>
      <origin rpy="1.57079632679 0 0" xyz="0 0 0"/>
      <geometry>
        <cylinder length="0.0254" radius="0.0762"/>
      </geometry>
    </collision>
  </link>
  <!-- Casters -->
  <link name="swivel_right"/>
  <link name="swivel_left"/>
  <link name="caster_right">
    <inertial>
      <mass value="0.040000"/>
      <origin xyz="0 0 0"/>
      <inertia ixx="0.000060" ixy="0.000000" ixz="0.000000" iyy="0.000060" iyz="0.000000" izz="0.000116"/>
    </inertial>
    <visual>
      <origin rpy="1.57079632679 0 0" xyz="0 0 0"/>
      <geometry>
        <cylinder length="0.0254" radius="0.0508"/>
      </geometry>
      <material name="Black">
        <color rgba="0 0 0 1"/>
      </material>
    </visual>
    <collision>
      <origin rpy="1.57079632679 0 0" xyz="0 0 0"/>
      <geometry>
        <cylinder length="0.0254" radius="0.0508"/>
      </geometry>
    </collision>
  </link>
  <link name="caster_left">
    <inertial>
      <mass value="0.040000"/>
      <origin xyz="0 0 0"/>
      <inertia ixx="0.000060" ixy="0.000000" ixz="0.000000" iyy="0.000060" iyz="0.000000" izz="0.000116"/>
    </inertial>
    <visual>
      <origin rpy="1.57079632679 0 0" xyz="0 0 0"/>
      <geometry>
        <cylinder length="0.0254" radius="0.0508"/>
      </geometry>
      <material name="Black">
        <color rgba="0 0 0 1"/>
      </material>
    </visual>
    <collision>
      <origin rpy="1.57079632679 0 0" xyz="0 0 0"/>
      <geometry>
        <cylinder length="0.0254" radius="0.0508"/>
      </geometry>
    </collision>
  </link>
  <joint name="base_joint" type="fixed">
    <origin rpy="0 0 0" xyz="0 0 0.12"/>
    <parent link="base_footprint"/>
    <child link="base_link"/>
  </joint>
  <joint name="seat_joint" type="fixed">
    <origin rpy="0 0 0" xyz="0 0 0.127"/>
    <parent link="base_link"/>
    <child link="seat_link"/>
  </joint>
  <joint name="arms_joint" type="fixed">
    <origin rpy="0 0 0" xyz="-0.1143 0 0.0635"/>
    <parent link="seat_link"/>
    <child link="arms_link"/>
  </joint>
  <joint name="back_joint" type="fixed">
    <origin rpy="0 0 0" xyz="0 0 0"/>
    <parent link="arms_link"/>
    <child link="back_link"/>
  </joint>
  <joint name="gearbox_plate_right_joint" type="fixed">
    <origin rpy="0 0 0" xyz="0.1243 -0.14835 0.01"/>
    <parent link="base_link"/>
    <child link="gearbox_plate_right"/>
  </joint>
  <joint name="gearbox_plate_left_joint" type="fixed">
    <origin rpy="0 0 0" xyz="0.1243 0.14835 0.01"/>
    <parent link="base_link"/>
    <child link="gearbox_plate_left"/>
  </joint>
  <joint name="wheel_right_joint" type="continuous">
    <axis xyz="0 1 0"/>
    <origin rpy="0 0 0" xyz="0 -0.02 0"/>
    <parent link="wheel_axle_right"/>
    <child link="wheel_right"/>
  </joint>
  <joint name="wheel_left_joint" type="continuous">
    <axis xyz="0 1 0"/>
    <origin rpy="0 0 0" xyz="0 +0.02 0"/>
    <parent link="wheel_axle_left"/>
    <child link="wheel_left"/>
  </joint>
  <joint name="swivel_right_joint" type="continuous">
    <axis xyz="0 0 1"/>
    <origin rpy="0 0 0" xyz="-0.2213 -0.13335 0.0508"/>
    <parent link="base_link"/>
    <child link="swivel_right"/>
  </joint>
  <joint name="swivel_left_joint" type="continuous">
    <axis xyz="0 0 1"/>
    <origin rpy="0 0 0" xyz="-0.2213 0.13335 0.0508"/>
    <parent link="base_link"/>
    <child link="swivel_left"/>
  </joint>
  <joint name="caster_right_joint" type="continuous">
    <axis xyz="0 1 0"/>
    <origin rpy="0 0 0" xyz="-0.0458 0 -0.12"/>
    <parent link="swivel_right"/>
    <child link="caster_right"/>
  </joint>
  <joint name="caster_left_joint" type="continuous">
    <axis xyz="0 1 0"/>
    <origin rpy="0 0 0" xyz="-0.0458 0 -0.12"/>
    <parent link="swivel_left"/>
    <child link="caster_left"/>
  </joint>
</robot>
